Tuesday, 02/27/18 February 2018 18:11:28 - telegram.ext.updater - ERROR - Error while getting Updates: Timed out
Tuesday, 02/27/18 February 2018 18:11:28 - telegram.ext.dispatcher - ERROR - An uncaught error was raised while handling the error
Traceback (most recent call last):
  File "D:\Python\lib\site-packages\telegram\vendor\ptb_urllib3\urllib3\connectionpool.py", line 402, in _make_request
    six.raise_from(e, None)
  File "<string>", line 2, in raise_from
  File "D:\Python\lib\site-packages\telegram\vendor\ptb_urllib3\urllib3\connectionpool.py", line 398, in _make_request
    httplib_response = conn.getresponse()
  File "D:\Python\lib\http\client.py", line 1331, in getresponse
    response.begin()
  File "D:\Python\lib\http\client.py", line 297, in begin
    version, status, reason = self._read_status()
  File "D:\Python\lib\http\client.py", line 258, in _read_status
    line = str(self.fp.readline(_MAXLINE + 1), "iso-8859-1")
  File "D:\Python\lib\socket.py", line 586, in readinto
    return self._sock.recv_into(b)
  File "D:\Python\lib\ssl.py", line 1002, in recv_into
    return self.read(nbytes, buffer)
  File "D:\Python\lib\ssl.py", line 865, in read
    return self._sslobj.read(len, buffer)
  File "D:\Python\lib\ssl.py", line 625, in read
    v = self._sslobj.read(len, buffer)
socket.timeout: The read operation timed out

During handling of the above exception, another exception occurred:

Traceback (most recent call last):
  File "D:\Python\lib\site-packages\telegram\utils\request.py", line 190, in _request_wrapper
    resp = self._con_pool.request(*args, **kwargs)
  File "D:\Python\lib\site-packages\telegram\vendor\ptb_urllib3\urllib3\request.py", line 70, in request
    **urlopen_kw)
  File "D:\Python\lib\site-packages\telegram\vendor\ptb_urllib3\urllib3\request.py", line 148, in request_encode_body
    return self.urlopen(method, url, **extra_kw)
  File "D:\Python\lib\site-packages\telegram\vendor\ptb_urllib3\urllib3\poolmanager.py", line 244, in urlopen
    response = conn.urlopen(method, u.request_uri, **kw)
  File "D:\Python\lib\site-packages\telegram\vendor\ptb_urllib3\urllib3\connectionpool.py", line 666, in urlopen
    _stacktrace=sys.exc_info()[2])
  File "D:\Python\lib\site-packages\telegram\vendor\ptb_urllib3\urllib3\util\retry.py", line 347, in increment
    raise six.reraise(type(error), error, _stacktrace)
  File "D:\Python\lib\site-packages\telegram\vendor\ptb_urllib3\urllib3\packages\six.py", line 686, in reraise
    raise value
  File "D:\Python\lib\site-packages\telegram\vendor\ptb_urllib3\urllib3\connectionpool.py", line 617, in urlopen
    chunked=chunked)
  File "D:\Python\lib\site-packages\telegram\vendor\ptb_urllib3\urllib3\connectionpool.py", line 405, in _make_request
    exc_cls=ReadTimeoutError)
  File "D:\Python\lib\site-packages\telegram\vendor\ptb_urllib3\urllib3\connectionpool.py", line 321, in _raise_timeout
    raise exc_cls(*args)
telegram.vendor.ptb_urllib3.urllib3.exceptions.ReadTimeoutError: HTTPSConnectionPool(host='api.telegram.org', port=443): Read timed out. (read timeout=12.0)

During handling of the above exception, another exception occurred:

Traceback (most recent call last):
  File "d:\gitProject\telegram-bot\exception.py", line 13, in error_callback
    raise error
  File "D:\Python\lib\site-packages\telegram\ext\updater.py", line 286, in _start_polling
    allowed_updates=allowed_updates)
  File "D:\Python\lib\site-packages\telegram\bot.py", line 60, in decorator
    result = func(self, *args, **kwargs)
  File "D:\Python\lib\site-packages\telegram\bot.py", line 1720, in get_updates
    result = self._request.post(url, data, timeout=float(read_latency) + float(timeout))
  File "D:\Python\lib\site-packages\telegram\utils\request.py", line 272, in post
    **urlopen_kwargs)
  File "D:\Python\lib\site-packages\telegram\utils\request.py", line 192, in _request_wrapper
    raise TimedOut()
telegram.error.TimedOut: Timed out

During handling of the above exception, another exception occurred:

Traceback (most recent call last):
  File "D:\Python\lib\site-packages\telegram\ext\dispatcher.py", line 271, in process_update
    self.dispatch_error(None, update)
  File "D:\Python\lib\site-packages\telegram\ext\dispatcher.py", line 384, in dispatch_error
    callback(self.bot, update, error)
  File "d:\gitProject\telegram-bot\exception.py", line 19, in error_callback
    updates.message.reply_text("等一会等一会~奶爸有点忙！")
AttributeError: 'NoneType' object has no attribute 'message'
Tuesday, 02/27/18 February 2018 18:17:27 - telegram.ext.updater - ERROR - Error while getting Updates: Timed out
Tuesday, 02/27/18 February 2018 18:17:27 - telegram.ext.dispatcher - ERROR - An uncaught error was raised while handling the error
Traceback (most recent call last):
  File "D:\Python\lib\site-packages\telegram\vendor\ptb_urllib3\urllib3\connectionpool.py", line 402, in _make_request
    six.raise_from(e, None)
  File "<string>", line 2, in raise_from
  File "D:\Python\lib\site-packages\telegram\vendor\ptb_urllib3\urllib3\connectionpool.py", line 398, in _make_request
    httplib_response = conn.getresponse()
  File "D:\Python\lib\http\client.py", line 1331, in getresponse
    response.begin()
  File "D:\Python\lib\http\client.py", line 297, in begin
    version, status, reason = self._read_status()
  File "D:\Python\lib\http\client.py", line 258, in _read_status
    line = str(self.fp.readline(_MAXLINE + 1), "iso-8859-1")
  File "D:\Python\lib\socket.py", line 586, in readinto
    return self._sock.recv_into(b)
  File "D:\Python\lib\ssl.py", line 1002, in recv_into
    return self.read(nbytes, buffer)
  File "D:\Python\lib\ssl.py", line 865, in read
    return self._sslobj.read(len, buffer)
  File "D:\Python\lib\ssl.py", line 625, in read
    v = self._sslobj.read(len, buffer)
socket.timeout: The read operation timed out

During handling of the above exception, another exception occurred:

Traceback (most recent call last):
  File "D:\Python\lib\site-packages\telegram\utils\request.py", line 190, in _request_wrapper
    resp = self._con_pool.request(*args, **kwargs)
  File "D:\Python\lib\site-packages\telegram\vendor\ptb_urllib3\urllib3\request.py", line 70, in request
    **urlopen_kw)
  File "D:\Python\lib\site-packages\telegram\vendor\ptb_urllib3\urllib3\request.py", line 148, in request_encode_body
    return self.urlopen(method, url, **extra_kw)
  File "D:\Python\lib\site-packages\telegram\vendor\ptb_urllib3\urllib3\poolmanager.py", line 244, in urlopen
    response = conn.urlopen(method, u.request_uri, **kw)
  File "D:\Python\lib\site-packages\telegram\vendor\ptb_urllib3\urllib3\connectionpool.py", line 666, in urlopen
    _stacktrace=sys.exc_info()[2])
  File "D:\Python\lib\site-packages\telegram\vendor\ptb_urllib3\urllib3\util\retry.py", line 347, in increment
    raise six.reraise(type(error), error, _stacktrace)
  File "D:\Python\lib\site-packages\telegram\vendor\ptb_urllib3\urllib3\packages\six.py", line 686, in reraise
    raise value
  File "D:\Python\lib\site-packages\telegram\vendor\ptb_urllib3\urllib3\connectionpool.py", line 617, in urlopen
    chunked=chunked)
  File "D:\Python\lib\site-packages\telegram\vendor\ptb_urllib3\urllib3\connectionpool.py", line 405, in _make_request
    exc_cls=ReadTimeoutError)
  File "D:\Python\lib\site-packages\telegram\vendor\ptb_urllib3\urllib3\connectionpool.py", line 321, in _raise_timeout
    raise exc_cls(*args)
telegram.vendor.ptb_urllib3.urllib3.exceptions.ReadTimeoutError: HTTPSConnectionPool(host='api.telegram.org', port=443): Read timed out. (read timeout=12.0)

During handling of the above exception, another exception occurred:

Traceback (most recent call last):
  File "d:\gitProject\telegram-bot\exception.py", line 13, in error_callback
    raise error
  File "D:\Python\lib\site-packages\telegram\ext\updater.py", line 286, in _start_polling
    allowed_updates=allowed_updates)
  File "D:\Python\lib\site-packages\telegram\bot.py", line 60, in decorator
    result = func(self, *args, **kwargs)
  File "D:\Python\lib\site-packages\telegram\bot.py", line 1720, in get_updates
    result = self._request.post(url, data, timeout=float(read_latency) + float(timeout))
  File "D:\Python\lib\site-packages\telegram\utils\request.py", line 272, in post
    **urlopen_kwargs)
  File "D:\Python\lib\site-packages\telegram\utils\request.py", line 192, in _request_wrapper
    raise TimedOut()
telegram.error.TimedOut: Timed out

During handling of the above exception, another exception occurred:

Traceback (most recent call last):
  File "D:\Python\lib\site-packages\telegram\ext\dispatcher.py", line 271, in process_update
    self.dispatch_error(None, update)
  File "D:\Python\lib\site-packages\telegram\ext\dispatcher.py", line 384, in dispatch_error
    callback(self.bot, update, error)
  File "d:\gitProject\telegram-bot\exception.py", line 19, in error_callback
    updates.message.reply_text("等一会等一会~奶爸有点忙！")
AttributeError: 'NoneType' object has no attribute 'message'
Tuesday, 02/27/18 February 2018 18:21:30 - telegram.ext.updater - ERROR - Error while getting Updates: Timed out
Tuesday, 02/27/18 February 2018 18:21:30 - telegram.ext.dispatcher - ERROR - An uncaught error was raised while handling the error
Traceback (most recent call last):
  File "D:\Python\lib\site-packages\telegram\vendor\ptb_urllib3\urllib3\connectionpool.py", line 402, in _make_request
    six.raise_from(e, None)
  File "<string>", line 2, in raise_from
  File "D:\Python\lib\site-packages\telegram\vendor\ptb_urllib3\urllib3\connectionpool.py", line 398, in _make_request
    httplib_response = conn.getresponse()
  File "D:\Python\lib\http\client.py", line 1331, in getresponse
    response.begin()
  File "D:\Python\lib\http\client.py", line 297, in begin
    version, status, reason = self._read_status()
  File "D:\Python\lib\http\client.py", line 258, in _read_status
    line = str(self.fp.readline(_MAXLINE + 1), "iso-8859-1")
  File "D:\Python\lib\socket.py", line 586, in readinto
    return self._sock.recv_into(b)
  File "D:\Python\lib\ssl.py", line 1002, in recv_into
    return self.read(nbytes, buffer)
  File "D:\Python\lib\ssl.py", line 865, in read
    return self._sslobj.read(len, buffer)
  File "D:\Python\lib\ssl.py", line 625, in read
    v = self._sslobj.read(len, buffer)
socket.timeout: The read operation timed out

During handling of the above exception, another exception occurred:

Traceback (most recent call last):
  File "D:\Python\lib\site-packages\telegram\utils\request.py", line 190, in _request_wrapper
    resp = self._con_pool.request(*args, **kwargs)
  File "D:\Python\lib\site-packages\telegram\vendor\ptb_urllib3\urllib3\request.py", line 70, in request
    **urlopen_kw)
  File "D:\Python\lib\site-packages\telegram\vendor\ptb_urllib3\urllib3\request.py", line 148, in request_encode_body
    return self.urlopen(method, url, **extra_kw)
  File "D:\Python\lib\site-packages\telegram\vendor\ptb_urllib3\urllib3\poolmanager.py", line 244, in urlopen
    response = conn.urlopen(method, u.request_uri, **kw)
  File "D:\Python\lib\site-packages\telegram\vendor\ptb_urllib3\urllib3\connectionpool.py", line 666, in urlopen
    _stacktrace=sys.exc_info()[2])
  File "D:\Python\lib\site-packages\telegram\vendor\ptb_urllib3\urllib3\util\retry.py", line 347, in increment
    raise six.reraise(type(error), error, _stacktrace)
  File "D:\Python\lib\site-packages\telegram\vendor\ptb_urllib3\urllib3\packages\six.py", line 686, in reraise
    raise value
  File "D:\Python\lib\site-packages\telegram\vendor\ptb_urllib3\urllib3\connectionpool.py", line 617, in urlopen
    chunked=chunked)
  File "D:\Python\lib\site-packages\telegram\vendor\ptb_urllib3\urllib3\connectionpool.py", line 405, in _make_request
    exc_cls=ReadTimeoutError)
  File "D:\Python\lib\site-packages\telegram\vendor\ptb_urllib3\urllib3\connectionpool.py", line 321, in _raise_timeout
    raise exc_cls(*args)
telegram.vendor.ptb_urllib3.urllib3.exceptions.ReadTimeoutError: HTTPSConnectionPool(host='api.telegram.org', port=443): Read timed out. (read timeout=12.0)

During handling of the above exception, another exception occurred:

Traceback (most recent call last):
  File "d:\gitProject\telegram-bot\exception.py", line 13, in error_callback
    raise error
  File "D:\Python\lib\site-packages\telegram\ext\updater.py", line 286, in _start_polling
    allowed_updates=allowed_updates)
  File "D:\Python\lib\site-packages\telegram\bot.py", line 60, in decorator
    result = func(self, *args, **kwargs)
  File "D:\Python\lib\site-packages\telegram\bot.py", line 1720, in get_updates
    result = self._request.post(url, data, timeout=float(read_latency) + float(timeout))
  File "D:\Python\lib\site-packages\telegram\utils\request.py", line 272, in post
    **urlopen_kwargs)
  File "D:\Python\lib\site-packages\telegram\utils\request.py", line 192, in _request_wrapper
    raise TimedOut()
telegram.error.TimedOut: Timed out

During handling of the above exception, another exception occurred:

Traceback (most recent call last):
  File "D:\Python\lib\site-packages\telegram\ext\dispatcher.py", line 271, in process_update
    self.dispatch_error(None, update)
  File "D:\Python\lib\site-packages\telegram\ext\dispatcher.py", line 384, in dispatch_error
    callback(self.bot, update, error)
  File "d:\gitProject\telegram-bot\exception.py", line 19, in error_callback
    updates.message.reply_text("等一会等一会~奶爸有点忙！")
AttributeError: 'NoneType' object has no attribute 'message'
Tuesday, 02/27/18 February 2018 18:23:27 - telegram.ext.updater - ERROR - Error while getting Updates: Timed out
Tuesday, 02/27/18 February 2018 18:23:27 - telegram.ext.dispatcher - ERROR - An uncaught error was raised while handling the error
Traceback (most recent call last):
  File "D:\Python\lib\site-packages\telegram\vendor\ptb_urllib3\urllib3\connectionpool.py", line 402, in _make_request
    six.raise_from(e, None)
  File "<string>", line 2, in raise_from
  File "D:\Python\lib\site-packages\telegram\vendor\ptb_urllib3\urllib3\connectionpool.py", line 398, in _make_request
    httplib_response = conn.getresponse()
  File "D:\Python\lib\http\client.py", line 1331, in getresponse
    response.begin()
  File "D:\Python\lib\http\client.py", line 297, in begin
    version, status, reason = self._read_status()
  File "D:\Python\lib\http\client.py", line 258, in _read_status
    line = str(self.fp.readline(_MAXLINE + 1), "iso-8859-1")
  File "D:\Python\lib\socket.py", line 586, in readinto
    return self._sock.recv_into(b)
  File "D:\Python\lib\ssl.py", line 1002, in recv_into
    return self.read(nbytes, buffer)
  File "D:\Python\lib\ssl.py", line 865, in read
    return self._sslobj.read(len, buffer)
  File "D:\Python\lib\ssl.py", line 625, in read
    v = self._sslobj.read(len, buffer)
socket.timeout: The read operation timed out

During handling of the above exception, another exception occurred:

Traceback (most recent call last):
  File "D:\Python\lib\site-packages\telegram\utils\request.py", line 190, in _request_wrapper
    resp = self._con_pool.request(*args, **kwargs)
  File "D:\Python\lib\site-packages\telegram\vendor\ptb_urllib3\urllib3\request.py", line 70, in request
    **urlopen_kw)
  File "D:\Python\lib\site-packages\telegram\vendor\ptb_urllib3\urllib3\request.py", line 148, in request_encode_body
    return self.urlopen(method, url, **extra_kw)
  File "D:\Python\lib\site-packages\telegram\vendor\ptb_urllib3\urllib3\poolmanager.py", line 244, in urlopen
    response = conn.urlopen(method, u.request_uri, **kw)
  File "D:\Python\lib\site-packages\telegram\vendor\ptb_urllib3\urllib3\connectionpool.py", line 666, in urlopen
    _stacktrace=sys.exc_info()[2])
  File "D:\Python\lib\site-packages\telegram\vendor\ptb_urllib3\urllib3\util\retry.py", line 347, in increment
    raise six.reraise(type(error), error, _stacktrace)
  File "D:\Python\lib\site-packages\telegram\vendor\ptb_urllib3\urllib3\packages\six.py", line 686, in reraise
    raise value
  File "D:\Python\lib\site-packages\telegram\vendor\ptb_urllib3\urllib3\connectionpool.py", line 617, in urlopen
    chunked=chunked)
  File "D:\Python\lib\site-packages\telegram\vendor\ptb_urllib3\urllib3\connectionpool.py", line 405, in _make_request
    exc_cls=ReadTimeoutError)
  File "D:\Python\lib\site-packages\telegram\vendor\ptb_urllib3\urllib3\connectionpool.py", line 321, in _raise_timeout
    raise exc_cls(*args)
telegram.vendor.ptb_urllib3.urllib3.exceptions.ReadTimeoutError: HTTPSConnectionPool(host='api.telegram.org', port=443): Read timed out. (read timeout=12.0)

During handling of the above exception, another exception occurred:

Traceback (most recent call last):
  File "d:\gitProject\telegram-bot\exception.py", line 13, in error_callback
    raise error
  File "D:\Python\lib\site-packages\telegram\ext\updater.py", line 286, in _start_polling
    allowed_updates=allowed_updates)
  File "D:\Python\lib\site-packages\telegram\bot.py", line 60, in decorator
    result = func(self, *args, **kwargs)
  File "D:\Python\lib\site-packages\telegram\bot.py", line 1720, in get_updates
    result = self._request.post(url, data, timeout=float(read_latency) + float(timeout))
  File "D:\Python\lib\site-packages\telegram\utils\request.py", line 272, in post
    **urlopen_kwargs)
  File "D:\Python\lib\site-packages\telegram\utils\request.py", line 192, in _request_wrapper
    raise TimedOut()
telegram.error.TimedOut: Timed out

During handling of the above exception, another exception occurred:

Traceback (most recent call last):
  File "D:\Python\lib\site-packages\telegram\ext\dispatcher.py", line 271, in process_update
    self.dispatch_error(None, update)
  File "D:\Python\lib\site-packages\telegram\ext\dispatcher.py", line 384, in dispatch_error
    callback(self.bot, update, error)
  File "d:\gitProject\telegram-bot\exception.py", line 19, in error_callback
    updates.message.reply_text("等一会等一会~奶爸有点忙！")
AttributeError: 'NoneType' object has no attribute 'message'
Tuesday, 02/27/18 February 2018 18:26:38 - telegram.ext.updater - ERROR - Error while getting Updates: Timed out
Tuesday, 02/27/18 February 2018 18:26:38 - telegram.ext.dispatcher - ERROR - An uncaught error was raised while handling the error
Traceback (most recent call last):
  File "D:\Python\lib\site-packages\telegram\vendor\ptb_urllib3\urllib3\connectionpool.py", line 402, in _make_request
    six.raise_from(e, None)
  File "<string>", line 2, in raise_from
  File "D:\Python\lib\site-packages\telegram\vendor\ptb_urllib3\urllib3\connectionpool.py", line 398, in _make_request
    httplib_response = conn.getresponse()
  File "D:\Python\lib\http\client.py", line 1331, in getresponse
    response.begin()
  File "D:\Python\lib\http\client.py", line 297, in begin
    version, status, reason = self._read_status()
  File "D:\Python\lib\http\client.py", line 258, in _read_status
    line = str(self.fp.readline(_MAXLINE + 1), "iso-8859-1")
  File "D:\Python\lib\socket.py", line 586, in readinto
    return self._sock.recv_into(b)
  File "D:\Python\lib\ssl.py", line 1002, in recv_into
    return self.read(nbytes, buffer)
  File "D:\Python\lib\ssl.py", line 865, in read
    return self._sslobj.read(len, buffer)
  File "D:\Python\lib\ssl.py", line 625, in read
    v = self._sslobj.read(len, buffer)
socket.timeout: The read operation timed out

During handling of the above exception, another exception occurred:

Traceback (most recent call last):
  File "D:\Python\lib\site-packages\telegram\utils\request.py", line 190, in _request_wrapper
    resp = self._con_pool.request(*args, **kwargs)
  File "D:\Python\lib\site-packages\telegram\vendor\ptb_urllib3\urllib3\request.py", line 70, in request
    **urlopen_kw)
  File "D:\Python\lib\site-packages\telegram\vendor\ptb_urllib3\urllib3\request.py", line 148, in request_encode_body
    return self.urlopen(method, url, **extra_kw)
  File "D:\Python\lib\site-packages\telegram\vendor\ptb_urllib3\urllib3\poolmanager.py", line 244, in urlopen
    response = conn.urlopen(method, u.request_uri, **kw)
  File "D:\Python\lib\site-packages\telegram\vendor\ptb_urllib3\urllib3\connectionpool.py", line 666, in urlopen
    _stacktrace=sys.exc_info()[2])
  File "D:\Python\lib\site-packages\telegram\vendor\ptb_urllib3\urllib3\util\retry.py", line 347, in increment
    raise six.reraise(type(error), error, _stacktrace)
  File "D:\Python\lib\site-packages\telegram\vendor\ptb_urllib3\urllib3\packages\six.py", line 686, in reraise
    raise value
  File "D:\Python\lib\site-packages\telegram\vendor\ptb_urllib3\urllib3\connectionpool.py", line 617, in urlopen
    chunked=chunked)
  File "D:\Python\lib\site-packages\telegram\vendor\ptb_urllib3\urllib3\connectionpool.py", line 405, in _make_request
    exc_cls=ReadTimeoutError)
  File "D:\Python\lib\site-packages\telegram\vendor\ptb_urllib3\urllib3\connectionpool.py", line 321, in _raise_timeout
    raise exc_cls(*args)
telegram.vendor.ptb_urllib3.urllib3.exceptions.ReadTimeoutError: HTTPSConnectionPool(host='api.telegram.org', port=443): Read timed out. (read timeout=12.0)

During handling of the above exception, another exception occurred:

Traceback (most recent call last):
  File "d:\gitProject\telegram-bot\exception.py", line 13, in error_callback
    raise error
  File "D:\Python\lib\site-packages\telegram\ext\updater.py", line 286, in _start_polling
    allowed_updates=allowed_updates)
  File "D:\Python\lib\site-packages\telegram\bot.py", line 60, in decorator
    result = func(self, *args, **kwargs)
  File "D:\Python\lib\site-packages\telegram\bot.py", line 1720, in get_updates
    result = self._request.post(url, data, timeout=float(read_latency) + float(timeout))
  File "D:\Python\lib\site-packages\telegram\utils\request.py", line 272, in post
    **urlopen_kwargs)
  File "D:\Python\lib\site-packages\telegram\utils\request.py", line 192, in _request_wrapper
    raise TimedOut()
telegram.error.TimedOut: Timed out

During handling of the above exception, another exception occurred:

Traceback (most recent call last):
  File "D:\Python\lib\site-packages\telegram\ext\dispatcher.py", line 271, in process_update
    self.dispatch_error(None, update)
  File "D:\Python\lib\site-packages\telegram\ext\dispatcher.py", line 384, in dispatch_error
    callback(self.bot, update, error)
  File "d:\gitProject\telegram-bot\exception.py", line 19, in error_callback
    updates.message.reply_text("等一会等一会~奶爸有点忙！")
AttributeError: 'NoneType' object has no attribute 'message'
